Workbook
Name Bronze: 'Ficha de Personagem'!$AS$7:$AV$10
Name Inquisidor: 'Ficha de Personagem'!$AS$7:$AV$9

Sheet Ficha de Personagem
D2: Crônicas de Atlas | AS2: Hey! Hide these columns!
AM3: Nível
U4: Cleric / Clérigo | AB4: Acolyto | AG4: =IF(AM4<5,IMAGE(AU19,1),IF(AM4<9,IMAGE(AU20,2),IF(AM4<13,IMAGE(AU21,1),IF(AM4<17,IMAGE(AU22,2),IF(AM4<21,IMAGE(AU23,2)))))) | AM4: =IF(AND(AM6>=AV19,AM6<AV20),2,IF(AND(AM6>=AV20,AM6<AV21),3,IF(AND(AM6>=AV21,AM6<AV22),4,IF(AND(AM6>=AV22,AM6<AV23),5,IF(AND(AM6>=AV23,AM6<AV24),6,IF(AND(AM6>=AV24,AM6<AV25),7,IF(AND(AM6>=AV25,AM6<AV26),8,IF(AND(AM6>=AV26,AM6<AV27),9,IF(AND(AM6>=AV27,AM6<AV28),10,IF(AND(AM6>=AV28,AM6<AV29),11,IF(AND(AM6>=AV29,AM6<AV30),12,IF(AND(AM6>=AV30,AM6<AV31),13,IF(AND(AM6>=AV31,AM6<AV32),14,IF(AND(AM6>=AV32,AM6<AV33),15,IF(AND(AM6>=AV33,AM6<AV34),16,IF(AND(AM6>=AV34,AM6<AV35),17,IF(AND(AM6>=AV35,AM6<AV36),18,IF(AND(AM6>=AV36,AM6<AW19),19,IF(AND(AM6>=AW19,AM6<AW20),20,IF(AND(AM6>=AW20,AM6<AW21),20,IF(AND(AM6>=AW21),20,2))))))))))))))))))))) -> 2 | AS4: 1.3c
D5: Grace Halliwell | U5: CLASSE | AB5: ANTECEDENTE
B6: =if(and(D6="",U4="",U6="",AN4="",D15="",D20="",D25="",D30="",D35="",D40=""),"Click [File] then [Make a copy...] to use the sheet for yourself.","") | U6: Humano | AB6: Caótico e Bom | AM6: ='Missões'!F1 -> 0
B7: =if(and(D6="",U4="",U6="",AN4="",D15="",D20="",D25="",D30="",D35="",D40=""),"oi.","") | U7: RAÇA | AB7: ALINHAMENTO | AM7: Experiência
B8: Nome do Personagem | U8: Redzin | AB8: =IF(AM4<5,"Recruta",IF(AM4<9,"Aprendiz",IF(AM4<13,"Oficial",IF(AM4<17,"Sentinela",IF(AM4<21,"Arauto","Sem Rank"))))) -> Recruta | AM8: =IF(AM4=2,AV20-AM6,IF(AM4=3,AV21-AM6,IF(AM4=4,AV22-AM6,IF(AM4=5,AV23-AM6,IF(AM4=6,AV24-AM6,IF(AM4=7,AV25-AM6,IF(AM4=8,AV26-AM6,IF(AM4=9,AV27-AM6,IF(AM4=10,AV28-AM6,IF(AM4=11,AV29-AM6,IF(AM4=12,AV30-AM6,IF(AM4=13,AV31-AM6,IF(AM4=14,AV32-AM6,IF(AM4=15,AV33-AM6,IF(AM4=16,AV34-AM6,IF(AM4=17,AV35-AM6,IF(AM4=18,AV36-AM6,IF(AM4=19,AW19-AM6,IF(AM4=20,AW20-AM6,IF(AM4=20,AM6-AW21,"")))))))))))))))))))) -> 10
U9: NOME DO JOGADOR | AB9: Rank | AM9: =IF(AM4=20,"Herói de Atlas", "PRÓX. NÍVEL") -> PRÓX. NÍVEL
L11: INSPIRAÇÃO | AE11: Ouro total | AN11: =Mercado!Q2 -> 48 | AU11: =SE(AB16=1;MULT(SE('Habilidades Adicionais'!AW3 = 'Sorcerer/ Feiticeiro';);1);0) -> #ERROR!
D12: FOR | S12: 16 | W12: -1 | AA12: 9m | AU12: =IFERROR(__xludf.DUMMYFUNCTION("QUERY('Habilidades Adicionais'!C18:H31, ""SELECT D where E = 'Artificer'"")"),"#N/A") -> #N/A
D13: =if(D15="","",INT((D15-10)/2)) -> 2
I14: =if(AM4="","",CHOOSE(AM4,2,2,2,2,3,3,3,3,4,4,4,4,5,5,5,5,6,6,6,6)) -> 2 | L14: BÔNUS DE PROFICIÊNCIA | R14: Classe Armadura | V14: INICIATIVA | Z14: DESLOCAMENTO | AE14: Missões jogadas | AN14: ='Missões'!W2 -> 0 | AS14: Anão da Colina (Resiliência Anã) = 2
D15: 15 | AS15: Robusto /Tough Talento
R16: 1 | S16: Vida Máxima | V16: =AT17+AS16 -> 21 | AS16: =IF(R16=1,(AM4*2),IF(R16=2,(AM4+40),IF(R16=3,((AM4*2)+(AM4+40)),IF(R16=4,(AM4*1),IF(R16=5,((AM4*2)+(AM4*1)),IF(R16=6,(((AM4*2)+(AM4+20)+(AM4*1))),"")))))) -> 4
D17: DES | I17: 0 | J17: =if($I$14<>"",if(I17<>0,$I$14,0)+D13,"") -> 2 | K17: Força | R17: 0 | S17: =(V16) -> 21 | AE17: =IF(Y133="","[251x335+]",IMAGE(Y133)) | AS17: =IF(Or(U4=AT38,U4=AT40,U4=AT42,U4=AT43,U4=AT44,U4=AT46,U4=AT49,U4=AT51),AS38+D23+(O93-1)*(AZ38+D23),IF(OR(U4=AT41,U4=AT45,U4=AT47,U4=AT48),AS41+D23+(O93-1)*(AZ41+D23),IF(OR(U4=AT50,U4=AT52),AS50+D23+(O93-1)*(AZ50+D23),if(U4=AT39,AS39+D23+(O93-1)*(AZ39+D23),0)))) -> 17 | AT17: =SUM(AS19:AS33)+AS17 -> 17
D18: =if(D20="","",INT((D20-10)/2)) -> -1 | I18: 0 | J18: =if($I$14<>"",if(I18<>0,$I$14,0)+D18,"") -> -1 | K18: Destreza | AS18: 1lv
I19: 0 | J19: =IF($I$14<>"",IF(I19<>0,$I$14,0)+D23,"") -> 2 | K19: Constituição | S19: PONTOS DE VIDA ATUAIS | AS19: =IFERROR(VLOOKUP(AT38,$D$94:$R$106,12, false)*(AZ38+$D$23),"") | AT19: R1 | AU19: https://i.pinimg.com/originals/1d/5d/78/1d5d78835aa500ef0903db57be2eaacf.png | AV19: 0 | AW19: 500
D20: 8 | I20: 0 | J20: =if($I$14<>"",if(I20<>0,$I$14,0)+D28,"") -> 1 | K20: Inteligência | S20: Pontos Atuais | AS20: =IFERROR(VLOOKUP(AT39,$D$94:$R$106,12, false)*(AZ39+$D$23),"") | AT20: R2 | AU20: https://i.pinimg.com/originals/51/ad/1f/51ad1f6f545421e9fc05aa30ec108004.png | AV20: 10 | AW20: 550
I21: 1 | J21: =if($I$14<>"",if(I21<>0,$I$14,0)+D33,"") -> 5 | K21: Sabedoria | AS21: =IFERROR(VLOOKUP(AT40,$D$94:$R$106,12, false)*(AZ40+$D$23),"") | AT21: R3 | AU21: https://i.pinimg.com/originals/07/a5/5c/07a55cb489421a6023a0af605f5b8403.png | AV21: 22
D22: CON | I22: 1 | J22: =if($I$14<>"",if(I22<>0,$I$14,0)+D38,"") -> 1 | K22: Carisma | AS22: =IFERROR(VLOOKUP(AT41,$D$94:$R$106,12, false)*(AZ41+$D$23),"") | AT22: R4 | AU22: https://i.pinimg.com/736x/c9/bd/29/c9bd29d3d1410e20c4ef78fbe67ca131.jpg | AV22: 36
D23: =if(D25="","",INT((D25-10)/2)) -> 2 | I23: TESTES DE RESISTÊNCIA | S23: PONTOS DE VIDA TEMPORÁRIOS | AS23: =IFERROR(VLOOKUP(AT42,$D$94:$R$106,12, false)*(AZ42+$D$23),"") | AT23: R5 | AU23: https://i.pinimg.com/originals/16/7c/bc/167cbc22252bdc491686e427bd2198af.png | AV23: 51
I24: 0 | J24: (Jack of all trades) | AS24: =IFERROR(VLOOKUP(AT43,$D$94:$R$106,12, false)*(AZ43+$D$23),"") | AT24: R6 | AU24: https://i.pinimg.com/originals/e7/81/36/e781362eb9bfa4630a293e4ca259c92e.png | AV24: 68
D25: 15 | I25: 0 | J25: =IF(I25=1,$D$18+$I$14,IF(I25="e",$D$18+$I$14*2,IF(AND(I25=0, $I$24="h"),FLOOR(0.5*$I$14+$D$18,1),$D$18))) -> -1 | K25: Acrobacias | N25: (Des) | AS25: =IFERROR(VLOOKUP(AT44,$D$94:$R$106,12, false)*(AZ44+$D$23),"") | AV25: 87
I26: 0 | J26: =IF(I26=1,$D$33+$I$14,IF(I26="e",$D$33+$I$14*2,IF(AND(I26=0, $I$24="h"),FLOOR(0.5*$I$14+$D$33,1),$D$33))) -> 3 | K26: Lidar com Animais | O26: (Sab) | AS26: =IFERROR(VLOOKUP(AT45,$D$94:$R$106,12, false)*(AZ45+$D$23),"") | AV26: 108
D27: INT | I27: 0 | J27: =IF(I27=1,$D$28+$I$14,IF(I27="e",$D$28+$I$14*2,IF(AND(I27=0, $I$24="h"),FLOOR(0.5*$I$14+$D$28,1),$D$28))) -> 1 | K27: Arcanismo | N27: (Int) | AS27: =IFERROR(VLOOKUP(AT46,$D$94:$R$106,12, false)*(AZ46+$D$23),"") | AV27: 132
D28: =if(D30="","",INT((D30-10)/2)) -> 1 | I28: 0 | J28: =IF(I28=1,$D$13+$I$14,IF(I28="e",$D$13+$I$14*2,IF(AND(I28=0, $I$24="h"),FLOOR(0.5*$I$14+$D$13,1),$D$13))) -> 2 | K28: Atletismo | N28: (For) | T28: ITENS SINTONIZADOS | AS28: =IFERROR(VLOOKUP(AT47,$D$94:$R$106,12, false)*(AZ47+$D$23),"") | AV28: 158
I29: 0 | J29: =IF(I29=1,$D$38+$I$14,IF(I29="e",$D$38+$I$14*2,IF(AND(I29=0, $I$24="h"),FLOOR(0.5*$I$14+$D$38,1),$D$38))) -> -1 | K29: Enganação | N29: (Car) | AE29: APARÊNCIA DO PERSONAGEM | AS29: =IFERROR(VLOOKUP(AT48,$D$94:$R$106,12, false)*(AZ48+$D$23),"") | AV29: 187
D30: 12 | I30: 1 | J30: =IF(I30=1,$D$28+$I$14,IF(I30="e",$D$28+$I$14*2,IF(AND(I30=0, $I$24="h"),FLOOR(0.5*$I$14+$D$28,1),$D$28))) -> 3 | K30: História | M30: (Int) | AS30: =IFERROR(VLOOKUP(AT49,$D$94:$R$106,12, false)*(AZ49+$D$23),"") | AV30: 217
I31: 1 | J31: =IF(I31=1,$D$33+$I$14,IF(I31="e",$D$33+$I$14*2,IF(AND(I31=0, $I$24="h"),FLOOR(0.5*$I$14+$D$33,1),$D$33))) -> 5 | K31: Intuição | M31: (Sab) | S31: Armas Simples e Marciais | AA31: Ferramenta de Cartógrafo | AI31: Comum | AS31: =IFERROR(VLOOKUP(AT50,$D$94:$R$106,12, false)*(AZ50+$D$23),"") | AV31: 251
D32: SAB | I32: 0 | J32: =IF(I32=1,$D$38+$I$14,IF(I32="e",$D$38+$I$14*2,IF(AND(I32=0, $I$24="h"),FLOOR(0.5*$I$14+$D$38,1),$D$38))) -> -1 | K32: Intimidação | N32: (Car) | S32: Armaduras (Todas)Clerigo da Vida) | AS32: =IFERROR(VLOOKUP(AT51,$D$94:$R$106,12, false)*(AZ51+$D$23),"") | AV32: 287
D33: =if(D35="","",INT((D35-10)/2)) -> 3 | I33: 0 | J33: =IF(I33=1,$D$28+$I$14,IF(I33="e",$D$28+$I$14*2,IF(AND(I33=0, $I$24="h"),FLOOR(0.5*$I$14+$D$28,1),$D$28))) -> 1 | K33: Investigação | N33: (Int) | AS33: =IFERROR(VLOOKUP(AT52,$D$94:$R$106,12, false)*(AZ52+$D$23),"") | AV33: 325
I34: 1 | J34: =IF(I34=1,$D$33+$I$14,IF(I34="e",$D$33+$I$14*2,IF(AND(I34=0, $I$24="h"),FLOOR(0.5*$I$14+$D$33,1),$D$33))) -> 5 | K34: Medicina | N34: (Sab) | AV34: 365
D35: 16 | I35: 0 | J35: =IF(I35=1,$D$28+$I$14,IF(I35="e",$D$28+$I$14*2,IF(AND(I35=0, $I$24="h"),FLOOR(0.5*$I$14+$D$28,1),$D$28))) -> 1 | K35: Natureza | M35: (Int) | AV35: 408
I36: 1 | J36: =IF(I36=1,$D$33+$I$14,IF(I36="e",$D$33+$I$14*2,IF(AND(I36=0, $I$24="h"),FLOOR(0.5*$I$14+$D$33,1),$D$33))) -> 5 | K36: Percepção | N36: (Sab) | AV36: 453
D37: CAR | I37: 0 | J37: =IF(I37=1,$D$38+$I$14,IF(I37="e",$D$38+$I$14*2,IF(AND(I37=0, $I$24="h"),FLOOR(0.5*$I$14+$D$38,1),$D$38))) -> -1 | K37: Atuação | M37: (Car) | AS37: 1lv | AT37: Vidas | AZ37: Media
D38: =if(D40="","",INT((D40-10)/2)) -> -1 | I38: 0 | J38: =IF(I38=1,$D$38+$I$14,IF(I38="e",$D$38+$I$14*2,IF(AND(I38=0, $I$24="h"),FLOOR(0.5*$I$14+$D$38,1),$D$38))) -> -1 | K38: Persuasão | N38: (Car) | AS38: 8 | AT38: Artificer | AZ38: 5
I39: 1 | J39: =IF(I39=1,$D$28+$I$14,IF(I39="e",$D$28+$I$14*2,IF(AND(I39=0, $I$24="h"),FLOOR(0.5*$I$14+$D$28,1),$D$28))) -> 3 | K39: Religião | M39: (Int) | AS39: 12 | AT39: Barbarian / Bárbaro | AZ39: 7
D40: 8 | I40: 0 | J40: =IF(I40=1,$D$18+$I$14,IF(I40="e",$D$18+$I$14*2,IF(AND(I40=0, $I$24="h"),FLOOR(0.5*$I$14+$D$18,1),$D$18))) -> -1 | K40: Presdigitação | N40: (Des) | S40: PROF.ARMAS & ARMADURAS | AA40: PROF.ITENS & FERRAMENTAS | AI40: IDIOMAS | AS40: 8 | AT40: Bard / Bardo | AZ40: 5
I41: 0 | J41: =IF(I41=1,$D$18+$I$14,IF(I41="e",$D$18+$I$14*2,IF(AND(I41=0, $I$24="h"),FLOOR(0.5*$I$14+$D$18,1),$D$18))) -> -1 | K41: Furtividade | N41: (Des) | AS41: 10 | AT41: Blood Hunter | AZ41: 6
I42: 0 | J42: =IF(I42=1,$D$33+$I$14,IF(I42="e",$D$33+$I$14*2,IF(AND(I42=0, $I$24="h"),FLOOR(0.5*$I$14+$D$33,1),$D$33))) -> 3 | K42: Sobrevivência | N42: (Sab) | S42: Conjuração | AI42: 1 For 1 Con 1 Sab | AS42: 8 | AT42: Cleric / Clérigo | AZ42: 5
...

Sheet Missões
B1: XP Total | F1: =SUM(B9+B24+B39+B54+B69+B84+B99+B114+B129+B144+B159+B174+B189+B204+B219+B234+B249+B264+B279+B294+B309+B324+B339+B354+B369+B384+B399+B414+B429+B444+B459+B474+B489+B504+B519+B534+B549+B564+B579+B594+B609+B624+B639+B654+B669+B684+B699+B714+B729+B744+B759+B774+B789+B804+B819+B834+B849+B864+B879+B894+B909+B924+B939+B954+B969+B984+B999+B1014+B1029+B1044+B1059+B1074+B1089+B1104+B1119+B1134+B1149+B1164+B1179+B1194+B1209+B1224+B1239+B1254+B1269+B1284+B1299+B1314+B1329+B1344+B1359+B1374+B1389+B1404+B1419+B1434+B1449+B1464+B1479+B1494) -> 0 | I1: Ganhos Totais | M1: =SUM(M9+M24+M39+M54+M69+M84+M99+M114+M129+M144+M159+M174+M189+M204+M219+M234+M249+M264+M279+M294+M309+M324+M339+M354+M369+M384+M399+M414+M429+M444+M459+M474+M489+M504+M519+M534+M549+M564+M579+M594+M609+M624+M639+M654+M669+M684+M699+M714+M729+M744+M759+M774+M789+M804+M819+M834+M849+M864+M879+M894+M909+M924+M939+M954+M969+M984+M999+M1014+M1029+M1044+M1059+M1074+M1089+M1104+M1119+M1134+M1149+M1164+M1179+M1194+M1209+M1224+M1239+M1254+M1269+M1284+M1299+M1314+M1329+M1344+M1359+M1374+M1389+M1404+M1419+M1434+M1449+M1464+M1479+M1494)-(M17+M32+M47+M62+M77+M92+M107+M122+M137+M152+M167+M182+M197+M212+M227+M242+M257+M272+M287+M302+M317+M332+M347+M362+M377+M392+M407+M422+M437+M452+M467+M482+M497+M512+M527+M542+M557+M572+M587+M602+M617+M632+M647+M662+M677+M692+M707+M722+M737+M752+M767+M782+M797+M812+M827+M842+M857+M872+M887+M902+M917+M932+M947+M962+M977+M992+M1007+M1022+M1037+M1052+M1067+M1082+M1097+M1112+M1127+M1142+M1157+M1172+M1187+M1202+M1217+M1232+M1247+M1262+M1277+M1292+M1307+M1322+M1337+M1352+M1367+M1382+M1397+M1412+M1427+M1442+M1457+M1472+M1487+M1502) -> 0 | O1: =SUM(O9+O24+O39+O54+O69+O84+O99+O114+O129+O144+O159+O174+O189+O204+O219+O234+O249+O264+O279+O294+O309+O324+O339+O354+O369+O384+O399+O414+O429+O444+O459+O474+O489+O504+O519+O534+O549+O564+O579+O594+O609+O624+O639+O654+O669+O684+O699+O714+O729+O744+O759+O774+O789+O804+O819+O834+O849+O864+O879+O894+O909+O924+O939+O954+O969+O984+O999+O1014+O1029+O1044+O1059+O1074+O1089+O1104+O1119+O1134+O1149+O1164+O1179+O1194+O1209+O1224+O1239+O1254+O1269+O1284+O1299+O1314+O1329+O1344+O1359+O1374+O1389+O1404+O1419+O1434+O1449+O1464+O1479+O1494)-(O17+O32+O47+O62+O77+O92+O107+O122+O137+O152+O167+O182+O197+O212+O227+O242+O257+O272+O287+O302+O317+O332+O347+O362+O377+O392+O407+O422+O437+O452+O467+O482+O497+O512+O527+O542+O557+O572+O587+O602+O617+O632+O647+O662+O677+O692+O707+O722+O737+O752+O767+O782+O797+O812+O827+O842+O857+O872+O887+O902+O917+O932+O947+O962+O977+O992+O1007+O1022+O1037+O1052+O1067+O1082+O1097+O1112+O1127+O1142+O1157+O1172+O1187+O1202+O1217+O1232+O1247+O1262+O1277+O1292+O1307+O1322+O1337+O1352+O1367+O1382+O1397+O1412+O1427+O1442+O1457+O1472+O1487+O1502) -> 0 | Q1: =SUM(Q9+Q24+Q39+Q54+Q69+Q84+Q99+Q114+Q129+Q144+Q159+Q174+Q189+Q204+Q219+Q234+Q249+Q264+Q279+Q294+Q309+Q324+Q339+Q354+Q369+Q384+Q399+Q414+Q429+Q444+Q459+Q474+Q489+Q504+Q519+Q534+Q549+Q564+Q579+Q594+Q609+Q624+Q639+Q654+Q669+Q684+Q699+Q714+Q729+Q744+Q759+Q774+Q789+Q804+Q819+Q834+Q849+Q864+Q879+Q894+Q909+Q924+Q939+Q954+Q969+Q984+Q999+Q1014+Q1029+Q1044+Q1059+Q1074+Q1089+Q1104+Q1119+Q1134+Q1149+Q1164+Q1179+Q1194+Q1209+Q1224+Q1239+Q1254+Q1269+Q1284+Q1299+Q1314+Q1329+Q1344+Q1359+Q1374+Q1389+Q1404+Q1419+Q1434+Q1449+Q1464+Q1479+Q1494)-(Q17+Q32+Q47+Q62+Q77+Q92+Q107+Q122+Q137+Q152+Q167+Q182+Q197+Q212+Q227+Q242+Q257+Q272+Q287+Q302+Q317+Q332+Q347+Q362+Q377+Q392+Q407+Q422+Q437+Q452+Q467+Q482+Q497+Q512+Q527+Q542+Q557+Q572+Q587+Q602+Q617+Q632+Q647+Q662+Q677+Q692+Q707+Q722+Q737+Q752+Q767+Q782+Q797+Q812+Q827+Q842+Q857+Q872+Q887+Q902+Q917+Q932+Q947+Q962+Q977+Q992+Q1007+Q1022+Q1037+Q1052+Q1067+Q1082+Q1097+Q1112+Q1127+Q1142+Q1157+Q1172+Q1187+Q1202+Q1217+Q1232+Q1247+Q1262+Q1277+Q1292+Q1307+Q1322+Q1337+Q1352+Q1367+Q1382+Q1397+Q1412+Q1427+Q1442+Q1457+Q1472+Q1487+Q1502) -> 0 | S1: =SUM(S9+S24+S39+S54+S69+S84+S99+S114+S129+S144+S159+S174+S189+S204+S219+S234+S249+S264+S279+S294+S309+S324+S339+S354+S369+S384+S399+S414+S429+S444+S459+S474+S489+S504+S519+S534+S549+S564+S579+S594+S609+S624+S639+S654+S669+S684+S699+S714+S729+S744+S759+S774+S789+S804+S819+S834+S849+S864+S879+S894+S909+S924+S939+S954+S969+S984+S999+S1014+S1029+S1044+S1059+S1074+S1089+S1104+S1119+S1134+S1149+S1164+S1179+S1194+S1209+S1224+S1239+S1254+S1269+S1284+S1299+S1314+S1329+S1344+S1359+S1374+S1389+S1404+S1419+S1434+S1449+S1464+S1479+S1494)-(S17+S32+S47+S62+S77+S92+S107+S122+S137+S152+S167+S182+S197+S212+S227+S242+S257+S272+S287+S302+S317+S332+S347+S362+S377+S392+S407+S422+S437+S452+S467+S482+S497+S512+S527+S542+S557+S572+S587+S602+S617+S632+S647+S662+S677+S692+S707+S722+S737+S752+S767+S782+S797+S812+S827+S842+S857+S872+S887+S902+S917+S932+S947+S962+S977+S992+S1007+S1022+S1037+S1052+S1067+S1082+S1097+S1112+S1127+S1142+S1157+S1172+S1187+S1202+S1217+S1232+S1247+S1262+S1277+S1292+S1307+S1322+S1337+S1352+S1367+S1382+S1397+S1412+S1427+S1442+S1457+S1472+S1487+S1502) -> 0 | U1: =SUM(U9+U24+U39+U54+U69+U84+U99+U114+U129+U144+U159+U174+U189+U204+U219+U234+U249+U264+U279+U294+U309+U324+U339+U354+U369+U384+U399+U414+U429+U444+U459+U474+U489+U504+U519+U534+U549+U564+U579+U594+U609+U624+U639+U654+U669+U684+U699+U714+U729+U744+U759+U774+U789+U804+U819+U834+U849+U864+U879+U894+U909+U924+U939+U954+U969+U984+U999+U1014+U1029+U1044+U1059+U1074+U1089+U1104+U1119+U1134+U1149+U1164+U1179+U1194+U1209+U1224+U1239+U1254+U1269+U1284+U1299+U1314+U1329+U1344+U1359+U1374+U1389+U1404+U1419+U1434+U1449+U1464+U1479+U1494)-(U17+U32+U47+U62+U77+U92+U107+U122+U137+U152+U167+U182+U197+U212+U227+U242+U257+U272+U287+U302+U317+U332+U347+U362+U377+U392+U407+U422+U437+U452+U467+U482+U497+U512+U527+U542+U557+U572+U587+U602+U617+U632+U647+U662+U677+U692+U707+U722+U737+U752+U767+U782+U797+U812+U827+U842+U857+U872+U887+U902+U917+U932+U947+U962+U977+U992+U1007+U1022+U1037+U1052+U1067+U1082+U1097+U1112+U1127+U1142+U1157+U1172+U1187+U1202+U1217+U1232+U1247+U1262+U1277+U1292+U1307+U1322+U1337+U1352+U1367+U1382+U1397+U1412+U1427+U1442+U1457+U1472+U1487+U1502) -> 0
M2: PPL | O2: PO | Q2: PE | S2: PP | U2: PC | W2: =sum(W3:W1517) -> 0
W3: =if(ISBLANK(B5),"",1)
B4: NOME DA AVENTURA:
B6: DATA DA AVENTURA: | M6: MESTRE:
B8: NÚMERO DE RECOMPENSAS GANHAS: | M8: TOTAL DE RIQUEZA GANHA:
D9: =IF(ISBLANK(B5),"",IF(B9>1,"Recompensas Adquiridas",IF(B9=1,"Recompensa Adquirida","Missão Sem Recompensa")))
B10: ITENS OBTIDOS: | M10: ITENS UTILIZADOS:
M16: TOTAL DE RIQUEZA GASTA:
W18: =if(ISBLANK(B20),"",1)
B19: NOME DA AVENTURA:
B21: DATA DA AVENTURA: | M21: MESTRE:
B23: NÚMERO DE RECOMPENSAS GANHAS: | M23: TOTAL DE RIQUEZA GANHA:
D24: =IF(ISBLANK(B20),"",IF(B24>1,"Recompensas Adquiridas",IF(B24=1,"Recompensa Adquirida","Missão Sem Recompensa")))
B25: ITENS OBTIDOS: | M25: ITENS UTILIZADOS:
M31: TOTAL DE RIQUEZA GASTA:
W33: =if(ISBLANK(B35),"",1)
B34: NOME DA AVENTURA:
B36: DATA DA AVENTURA: | M36: MESTRE:
B38: NÚMERO DE RECOMPENSAS GANHAS: | M38: TOTAL DE RIQUEZA GANHA:
D39: =IF(ISBLANK(B35),"",IF(B39>1,"Recompensas Adquiridas",IF(B39=1,"Recompensa Adquirida","Missão Sem Recompensa")))
B40: ITENS OBTIDOS: | M40: ITENS UTILIZADOS:
M46: TOTAL DE RIQUEZA GASTA:
W48: =if(ISBLANK(B50),"",1)
B49: NOME DA AVENTURA:
B51: DATA DA AVENTURA: | M51: MESTRE:
B53: NÚMERO DE RECOMPENSAS GANHAS: | M53: TOTAL DE RIQUEZA GANHA:
D54: =IF(ISBLANK(B50),"",IF(B54>1,"Aventuras Adquiridas",IF(B54=1,"Aventura Adquirida","Missão Sem Aventura")))
B55: ITENS OBTIDOS: | M55: ITENS UTILIZADOS:
M61: TOTAL DE RIQUEZA GASTA:
W63: =if(ISBLANK(B65),"",1)
B64: NOME DA AVENTURA:
B66: DATA DA AVENTURA: | M66: MESTRE:
B68: NÚMERO DE RECOMPENSAS GANHAS: | M68: TOTAL DE RIQUEZA GANHA:
D69: =IF(ISBLANK(B65),"",IF(B69>1,"Aventuras Adquiridas",IF(B69=1,"Aventura Adquirida","Missão Sem Aventura")))
B70: ITENS OBTIDOS: | M70: ITENS UTILIZADOS:
M76: TOTAL DE RIQUEZA GASTA:
W78: =if(ISBLANK(B80),"",1)
B79: NOME DA AVENTURA:
B81: DATA DA AVENTURA: | M81: MESTRE:
...

Sheet Habilidades Adicionais
AW3: =IFERROR(__xludf.DUMMYFUNCTION("QUERY('Ficha de Personagem'!D93:I106, ""select C where C = 'Sorcerer/ Feiticeiro'"", -1)"),"#VALUE!") -> #VALUE!
C14: CARACTERÍSTICAS & HABILIDADES ADICIONAIS | W14: CARACTERÍSTICAS & HABILIDADES ADICIONAIS
BA17: Média de PV

Sheet Magias
A1: =if(and(C5<>"",countif(AQ69:AQ94,C5)),image(vlookup(C5,AQ69:AS94,2,false),2),image("http://i.imgur.com/Pnzh0Lq.png",2))
S2: =IMAGE("http://i.imgur.com/2jwsXWa.png",2)
S3: =IMAGE("http://i.imgur.com/1aZcJXU.png",2) | AO3: =IMAGE("http://i.imgur.com/nWCUyCa.png",2)
T4: =IMAGE("http://i.imgur.com/bMB1ljY.png",2) | U4: HABILIDADE DE | Y4: =IMAGE("http://i.imgur.com/vGypnz4.png",2) | AA4: =IMAGE("http://i.imgur.com/bMB1ljY.png",2) | AB4: CLASSE DE | AF4: =IMAGE("http://i.imgur.com/vGypnz4.png",2) | AH4: =IMAGE("http://i.imgur.com/bMB1ljY.png",2) | AI4: BÔNUS DE ATAQUE | AM4: =IMAGE("http://i.imgur.com/vGypnz4.png",2)
AQ5: =IFERROR(__xludf.DUMMYFUNCTION("iferror(transpose(split(textjoin(""~"",True,iferror(filter(#REF!,#REF!<>""""),""""),if(isnumber(find(""magic initiate"",#REF!)),unique(iferror(filter(#REF!,#REF!<>"""",isnumber(find(lower(#REF!),regexextract(#REF!,""initiate..[a-z]+."")))),"""")),"""")),"&"""~"")),"""")"),"") | AR5: =IFERROR(__xludf.DUMMYFUNCTION("sum(arrayformula(int(iferror(trim(left(regexextract(lower(filter({BA$32:BA$56;Additional!$BA$3:$BA$24},regexmatch(lower({BA$32:BA$56;Additional!$BA$3:$BA$24}),""[0-9]+ bonus to spell attack rolls""))),""[0-9]+ bonus to spell attack""),2)),0)))) +sum(array"&"formula(int(iferror(trim(right(regexextract(lower(filter({BA$32:BA$56;Additional!$BA$3:$BA$24},regexmatch(lower({BA$32:BA$56;Additional!$BA$3:$BA$24}),""spell attack bonus[a-z ]+increase[a-z ]+[0-9]+""))),""increase[a-z ]+[0-9]+""),2)),0))))"),0.0) -> 0
A7: =IMAGE("http://i.imgur.com/EmUh8kY.png",2) | U7: CONJURAÇÃO | AB7: DIFICULDADE | AI7: DO FEITIÇO
S8: =IMAGE("http://i.imgur.com/M5KNO4X.png",2)
D9: Mestre de Batalha (Battle Master) | AO9: =IMAGE("http://i.imgur.com/NNIwrh4.png",3)
A10: =IMAGE("http://i.imgur.com/S2iZUIk.png") | B10: =IF(C9="m", "☆", "0") -> 0 | L10: c | T10: =IMAGE("http://i.imgur.com/1atTEws.png",3) | V10: c | AD10: =IMAGE("http://i.imgur.com/1atTEws.png",3) | AF10: c | AO10: =IMAGE("http://i.imgur.com/jVB4BpP.png")
L11: c | V11: c | AF11: c
E12: =IF(C9="m", "MANOBRAS", "TRUQUES") -> TRUQUES | L12: c | V12: c | AF12: c
L13: c | V13: c | AF13: c
L14: c | V14: c | AF14: c
AQ15: =IFERROR(__xludf.DUMMYFUNCTION("if(countif(#REF!,""Pact Magic""),if(sum(filter($AT$6:$AT$22,$AX$6:$AX$22=""Pact Magic"")),choose(sum(filter($AT$6:$AT$22,$AX$6:$AX$22=""Pact Magic"")),1,2,"""","""","""","""","""","""","""","""","""","""","""","""","""","""","""","""","""",""""),""""),"""&""")"),"")
A16: =IMAGE("http://i.imgur.com/BMbfOFs.png") | B16: =IMAGE("https://i.imgur.com/215d4SQ.png",2) | F16: =IMAGE("http://i.imgur.com/4ww92Ws.png",2) | J16: =IMAGE("http://i.imgur.com/GYlWKEy.png",2) | K16: =IMAGE("http://i.imgur.com/Pb1Q0X9.png") | P16: =IMAGE("http://i.imgur.com/BMbfOFs.png") | Q16: =IMAGE("https://i.imgur.com/azAgS7f.png",2) | U16: =IMAGE("http://i.imgur.com/4ww92Ws.png",2) | Y16: =IMAGE("http://i.imgur.com/GYlWKEy.png",2) | Z16: =IMAGE("http://i.imgur.com/Pb1Q0X9.png") | AE16: =IMAGE("http://i.imgur.com/BMbfOFs.png") | AF16: =IMAGE("https://i.imgur.com/gSVI169.png",2) | AJ16: =IMAGE("http://i.imgur.com/4ww92Ws.png",2) | AN16: =IMAGE("http://i.imgur.com/GYlWKEy.png",2) | AO16: =IMAGE("http://i.imgur.com/Pb1Q0X9.png") | AQ16: =if(and(#REF!<>"",#REF!>0),choose(#REF!,2,3,4,4,4,4,4,4,4,4,4,4,4,4,4,4,4,4,4,4),"") -> #REF!
B20: 0 | Q20: 0 | AF20: 0
B21: 0 | Q21: 0 | AF21: 0 | AQ21: =IFERROR(__xludf.DUMMYFUNCTION("if(countif(#REF!,""Pact Magic""),if(sum(filter($AT$6:$AT$22,$AX$6:$AX$22=""Pact Magic"")),choose(sum(filter($AT$6:$AT$22,$AX$6:$AX$22=""Pact Magic"")),"""","""",2,2,"""","""","""","""","""","""","""","""","""","""","""","""","""","""","""",""""),""""),"""&""")"),"")
B22: 0 | Q22: 0 | AF22: 0 | AQ22: =if(and(#REF!<>"",#REF!>0),choose(#REF!,"","",2,3,3,3,3,3,3,3,3,3,3,3,3,3,3,3,3,3),"") -> #REF!
B23: 0 | Q23: 0 | AF23: 0
B24: 0 | Q24: 0 | AF24: 0
B25: 0 | Q25: 0 | AF25: 0
B26: 0 | Q26: 0 | AF26: 0
B27: 0 | Q27: 0 | AF27: 0 | AQ27: =IFERROR(__xludf.DUMMYFUNCTION("if(countif(#REF!,""Pact Magic""),if(sum(filter($AT$6:$AT$22,$AX$6:$AX$22=""Pact Magic"")),choose(sum(filter($AT$6:$AT$22,$AX$6:$AX$22=""Pact Magic"")),"""","""","""","""",2,2,"""","""","""","""","""","""","""","""","""","""","""","""","""",""""),""""),"""&""")"),"")
B28: 0 | Q28: 0 | AF28: 0 | AQ28: =if(and(#REF!<>"",#REF!>0),choose(#REF!,"","","","",2,3,3,3,3,3,3,3,3,3,3,3,3,3,3,3),"") -> #REF!
B29: 0 | Q29: 0 | AF29: 0
B30: 0 | Q30: 0 | AF30: 0
B31: 0 | Q31: 0 | AF31: 0
B32: 0 | Q32: 0 | AF32: 0
B33: 0 | Q33: 0 | AF33: 0 | AQ33: =IFERROR(__xludf.DUMMYFUNCTION("if(countif(#REF!,""Pact Magic""),if(sum(filter($AT$6:$AT$22,$AX$6:$AX$22=""Pact Magic"")),choose(sum(filter($AT$6:$AT$22,$AX$6:$AX$22=""Pact Magic"")),"""","""","""","""","""","""",2,2,"""","""","""","""","""","""","""","""","""","""","""",""""),""""),"""&""")"),"")
B34: 0 | Q34: 0 | AF34: 0 | AQ34: =if(and(#REF!<>"",#REF!>0),choose(#REF!,"","","","","","",1,2,3,3,3,3,3,3,3,3,3,3,3,3),"") -> #REF!
B35: 0 | Q35: 0 | AF35: 0
B36: 0 | Q36: 0 | AF36: 0
B37: 0 | Q37: 0 | AF37: 0
B38: 0 | Q38: 0 | AF38: 0 | AQ38: =IFERROR(__xludf.DUMMYFUNCTION("if(countif(#REF!,""Pact Magic""),if(sum(filter($AT$6:$AT$22,$AX$6:$AX$22=""Pact Magic"")),choose(sum(filter($AT$6:$AT$22,$AX$6:$AX$22=""Pact Magic"")),"""","""","""","""","""","""","""","""",2,2,3,3,3,3,3,3,4,4,4,4),""""),"""")"),"")
B39: 0 | Q39: 0 | AF39: 0 | AQ39: =if(and(#REF!<>"",#REF!>0),choose(#REF!,"","","","","","","","",1,2,2,2,2,2,2,2,2,3,3,3),"") -> #REF!
B40: 0 | Q40: 0 | AF40: 0
B41: 0 | Q41: 0 | AF41: 0
B42: 0 | Q42: 0 | AF42: 0
B43: 0 | Q43: 0 | AF43: 0
B44: 0 | Q44: 0 | AF44: 0
...

Sheet Mercado
G2: Ouro Total | Q2: =V6+K6 -> 48
B6: GASTOS TOTAIS: | K6: =-(Sum(K9:K985)) -> -10 | M6: GANHOS TOTAIS: | V6: =Sum(V9:V985) -> 58
B8: ITENS COMPRADOS: | I8: Data | J8: Origem | K8: Ouro | M8: ITENS VENDIDOS: | T8: Data | U8: Origem | V8: Ouro
B9: Healer Kit | J9: Mercado | K9: 10 | M9: Antecedente | V9: 8
M10: Aventuras | V10: ='Missões'!O1 -> 0
M11: Ajuda da guilda | V11: 50

Sheet Baú do Personagem
B6: # | C6: Descrição do Item | D6: Valor

Sheet Bestiário
B1: =IMAGE("http://i.imgur.com/1aZcJXU.png",2)
B2: BESTIÁRIO
B4: =IMAGE("http://i.imgur.com/M5KNO4X.png",2)
B5: Nome da Criatura: | I5: CD | J5: Tipo | K5: Nome da missão Encontrada: | T5: Data: | U5: Link 5etools:

Sheet Reputações
B1: Registro de reputações | AJ1: Niveis | AK1: Titulo | AL1: Nomes das facçoes | AM1: Imagens (URL)
R2: =AL2 -> Arcádia | Z2: =AL3 -> Astrávia | AJ2: -500 | AK2: Odiado | AL2: Arcádia | AM2: https://media.discordapp.net/attachments/915292109089677392/1123828121515343873/2a66af7d26ba92de33a3ac97b321b16f.jpg?width=430&height=646
R3: =IMAGE(AM2, 2) | Z3: =IMAGE(AM3, 2) | AJ3: -200 | AK3: Procurado | AL3: Astrávia | AM3: https://media.discordapp.net/attachments/915292109089677392/1123828122471641118/231e6e3341a025737096c67819425427.jpg?width=507&height=507
B4: DATA | D4: FACÇÃO | J4: VALOR | AJ4: 0 | AK4: Indiferente | AL4: Eradan | AM4: https://cdn.discordapp.com/attachments/735636320499793951/1124092872430461049/Eradan.png
AJ5: 100 | AK5: Respeitado | AL5: Ta'histe | AM5: https://media.discordapp.net/attachments/915292109089677392/1123828121058164756/6ec72047ce7ebb77870d119a5b4082e0.jpg?width=507&height=507
AJ6: 250 | AK6: Honrado | AL6: Mithra | AM6: https://media.discordapp.net/attachments/915292109089677392/1123828179442868355/6e79ff2ecfa69dd45f893c451c408544.jpg?width=469&height=461
AJ7: 500 | AK7: Reverenciado | AL7: Bellizia | AM7: https://media.discordapp.net/attachments/915292109089677392/1123828178922786956/276b633e62b6131dc24cf17ae3e607ab.jpg?width=507&height=507
AJ8: 1000 | AK8: Exaltado | AL8: Bra'has | AM8: https://media.discordapp.net/attachments/915292109089677392/1123828122794606653/f1770eb877e4754b77f73748f548d19b.jpg?width=507&height=511
AL9: Guilda Legião | AM9: https://media.discordapp.net/attachments/915292109089677392/1123828123033669673/c034b73c4ead3468cc762751c5bf3913.jpg?width=646&height=646
R11: =SUMIF($D$5:$D1001,$AL$2,$J$5:$J1001) -> 0 | T11: =if(R11<=AJ2,AK2,if(R11<=AJ3,AK3,if(R11>=AJ8,AK8,if(R11>=AJ7,AK7,if(R11>=AJ6,AK6,if(R11>=AJ5,AK5,AK4)))))) -> Indiferente | Z11: =SUMIF($D$5:$D1001,$AL$3,$J$5:$J1001) -> 0 | AB11: =if(Z11<=AJ2,AK2,if(Z11<=AJ3,AK3,if(Z11>=AJ8,AK8,if(Z11>=AJ7,AK7,if(Z11>=AJ6,AK6,if(Z11>=AJ5,AK5,AK4)))))) -> Indiferente
R13: =AL4 -> Eradan | Z13: =AL5 -> Ta'histe
R14: =IMAGE(AM4, 2) | Z14: =IMAGE(AM5)
R22: =SUMIF($D$5:$D1001,$AL$4,$J$5:$J1001) -> 0 | T22: =if(R22<=AJ2,AK2,if(R22<=AJ3,AK3,if(R22>=AJ5,AK5,if(R22>=AJ6,AK6,if(R22>=AJ7,AK7,if(R22>=AJ8,AK8,AK4)))))) -> Indiferente | Z22: =SUMIF($D$5:$D1001,$AL$5,$J$5:$J1001) -> 0 | AB22: =if(Z22<=AJ2,AK2,if(Z22<=AJ3,AK3,if(Z22>=AJ8,AK8,if(Z22>=AJ7,AK7,if(Z22>=AJ6,AK6,if(Z22>=AJ5,AK5,AK4)))))) -> Indiferente | AK22: ='Ficha de Personagem'!D5 -> Grace Halliwell
R24: =AL6 -> Mithra | Z24: =AL7 -> Bellizia | AK24: ='Ficha de Personagem'!D5 -> Grace Halliwell
R25: =IMAGE(AM6, 2) | Z25: =IMAGE(AM7, 2)
R33: =SUMIF($D$5:$D1001,$AL$6,$J$5:$J1001) -> 0 | T33: =if(R33<=AJ2,AK2,if(R33<=AJ3,AK3,if(R33>=AJ8,AK8,if(R33>=AJ7,AK7,if(R33>=AJ6,AK6,if(R33>=AJ5,AK5,AK4)))))) -> Indiferente | Z33: =SUMIF($D$5:$D1001,$AL$7,$J$5:$J1001) -> 0 | AB33: =if(Z33<=AJ2,AK2,if(Z33<=AJ3,AK3,if(Z33>=AJ8,AK8,if(Z33>=AJ7,AK7,if(Z33>=AJ6,AK6,if(Z33>=AJ5,AK5,AK4)))))) -> Indiferente
R36: =AL8 -> Bra'has | Z36: =AL9 -> Guilda Legião
R37: =IMAGE(AM8, 2) | Z37: =IMAGE(AM9, 2)
R45: =SUMIF($D$5:$D1001,$AL$6,$J$5:$J1001) -> 0 | T45: =if(R33<=AJ2,AK2,if(R33<=AJ3,AK3,if(R33>=AJ8,AK8,if(R33>=AJ7,AK7,if(R33>=AJ6,AK6,if(R33>=AJ5,AK5,AK4)))))) -> Indiferente | Z45: =SUMIF($D$5:$D1001,$AL$6,$J$5:$J1001) -> 0 | AB45: =if(R33<=AJ2,AK2,if(R33<=AJ3,AK3,if(R33>=AJ8,AK8,if(R33>=AJ7,AK7,if(R33>=AJ6,AK6,if(R33>=AJ5,AK5,AK4)))))) -> Indiferente

Sheet Missões Jogadas
C1: Aventuras Total | G1: =C9+C24+C39+C54+C69+C84+C99+C114+C129+C144+C159+C174+C189+C204+C219+C234+C249+C264+C279+C294+C309+C324+C339+C354+C369+C384+C399+C414+C429+C444+C459+C474+C489+C504+C519+C534+C549+C564+C579+C594+C609+C624+C639+C654+C669+C684+C699+C714+C729+C744+C759+C774+C789+C804+C819+C834+C849+C864+C879+C894+C909+C924+C939+C954+C969+C984+C999+C1014+C1029+C1044+C1059+C1074+C1089+C1104+C1119+C1134+C1149+C1164+C1179+C1194+C1209+C1224+C1239+C1254+C1269+C1284+C1299+C1314+C1329+C1344 -> 0
C4: NOME DA MISSÃO:
C6: MESTRE:
C8: EXPERIÊNCIA GANHA: | N8: DATA DA MISSÃO:
F9: =IF(ISBLANK(C5),"",IF(C9>1,"Experiências Adquiridas",IF(C9=1,"Experiência Adquirida","Missão Sem Experiência")))
C10: ITENS OBTIDOS: | N10: ITENS UTILIZADOS:
C19: NOME DA MISSÃO:
C21: MESTRE:
C23: EXPERIÊNCIA GANHA: | N23: DATA DA MISSÃO:
F24: =IF(ISBLANK(C20),"",IF(C24>1,"Experiências Adquiridas",IF(C24=1,"Experiência Adquirida","Missão Sem Experiência")))
C25: ITENS OBTIDOS: | N25: ITENS UTILIZADOS:
C34: NOME DA MISSÃO:
C36: MESTRE:
C38: EXPERIÊNCIA GANHA: | N38: DATA DA MISSÃO:
F39: =IF(ISBLANK(C35),"",IF(C39>1,"Experiências Adquiridas",IF(C39=1,"Experiência Adquirida","Missão Sem Experiência")))
C40: ITENS OBTIDOS: | N40: ITENS UTILIZADOS:
C49: NOME DA MISSÃO:
C51: MESTRE:
C53: EXPERIÊNCIA GANHA: | N53: DATA DA MISSÃO:
F54: =IF(ISBLANK(C50),"",IF(C54>1,"Experiências Adquiridas",IF(C54=1,"Experiência Adquirida","Missão Sem Experiência")))
C55: ITENS OBTIDOS: | N55: ITENS UTILIZADOS:
C64: NOME DA MISSÃO:
C66: MESTRE:
C68: EXPERIÊNCIA GANHA: | N68: DATA DA MISSÃO:
F69: =IF(ISBLANK(C65),"",IF(C69>1,"Experiências Adquiridas",IF(C69=1,"Experiência Adquirida","Missão Sem Experiência")))
C70: ITENS OBTIDOS: | N70: ITENS UTILIZADOS:
C79: NOME DA MISSÃO:
C81: MESTRE:
C83: EXPERIÊNCIA GANHA: | N83: DATA DA MISSÃO:
F84: =IF(ISBLANK(C80),"",IF(C84>1,"Experiências Adquiridas",IF(C84=1,"Experiência Adquirida","Missão Sem Experiência")))
C85: ITENS OBTIDOS: | N85: ITENS UTILIZADOS:
C94: NOME DA MISSÃO:
C96: MESTRE:
C98: EXPERIÊNCIA GANHA: | N98: DATA DA MISSÃO:
F99: =IF(ISBLANK(C95),"",IF(C99>1,"Experiências Adquiridas",IF(C99=1,"Experiência Adquirida","Missão Sem Experiência")))
C100: ITENS OBTIDOS: | N100: ITENS UTILIZADOS:
C109: NOME DA MISSÃO:
C111: MESTRE:
C113: EXPERIÊNCIA GANHA: | N113: DATA DA MISSÃO:
F114: =IF(ISBLANK(C110),"",IF(C114>1,"Experiências Adquiridas",IF(C114=1,"Experiência Adquirida","Missão Sem Experiência")))
...

Sheet OUTRAS INFORMAÇÕES
C51: NOME
C52: CA | F52: PV | I52: / | K52: DESLOC.
C53: FOR | E53: DES | G53: CON | I53: INT | K53: SAB | M53: CAR
D54: =if(C54="","( )",INT((C54-10)/2)) -> ( ) | F54: =if(E54="","( )",INT((E54-10)/2)) -> ( ) | H54: =if(G54="","( )",INT((G54-10)/2)) -> ( ) | J54: =if(I54="","( )",INT((I54-10)/2)) -> ( ) | L54: =if(K54="","( )",INT((K54-10)/2)) -> ( ) | N54: =if(M54="","( )",INT((M54-10)/2)) -> ( )
C58: COMPANHEIRO

Sheet História de Origem
